[2024-05-06T21:57:30.089-0500] {local_task_job_runner.py:120} INFO - ::group::Pre task execution logs
[2024-05-06T21:57:30.119-0500] {taskinstance.py:2073} INFO - Dependencies all met for dep_context=non-requeueable deps ti=<TaskInstance: mysql_to_excel_report.export_to_excel manual__2024-05-07T02:57:26.744042+00:00 [queued]>
[2024-05-06T21:57:30.129-0500] {taskinstance.py:2073} INFO - Dependencies all met for dep_context=requeueable deps ti=<TaskInstance: mysql_to_excel_report.export_to_excel manual__2024-05-07T02:57:26.744042+00:00 [queued]>
[2024-05-06T21:57:30.130-0500] {taskinstance.py:2303} INFO - Starting attempt 1 of 1
[2024-05-06T21:57:30.149-0500] {taskinstance.py:2327} INFO - Executing <Task(PythonOperator): export_to_excel> on 2024-05-07 02:57:26.744042+00:00
[2024-05-06T21:57:30.155-0500] {standard_task_runner.py:63} INFO - Started process 65374 to run task
[2024-05-06T21:57:30.166-0500] {standard_task_runner.py:90} INFO - Running: ['airflow', 'tasks', 'run', 'mysql_to_excel_report', 'export_to_excel', 'manual__2024-05-07T02:57:26.744042+00:00', '--job-id', '11', '--raw', '--subdir', 'DAGS_FOLDER/first.py', '--cfg-path', '/var/folders/rk/p8h75rkd3ql6mqn01ypzqgnw0000gn/T/tmpa7y97vjj']
[2024-05-06T21:57:30.170-0500] {standard_task_runner.py:91} INFO - Job 11: Subtask export_to_excel
[2024-05-06T21:57:30.255-0500] {task_command.py:426} INFO - Running <TaskInstance: mysql_to_excel_report.export_to_excel manual__2024-05-07T02:57:26.744042+00:00 [running]> on host colpc-c02ylanslvcf.local
[2024-05-06T21:57:30.575-0500] {taskinstance.py:2644} INFO - Exporting env vars: AIRFLOW_CTX_DAG_OWNER='airflow' AIRFLOW_CTX_DAG_ID='mysql_to_excel_report' AIRFLOW_CTX_TASK_ID='export_to_excel' AIRFLOW_CTX_EXECUTION_DATE='2024-05-07T02:57:26.744042+00:00' AIRFLOW_CTX_TRY_NUMBER='1' AIRFLOW_CTX_DAG_RUN_ID='manual__2024-05-07T02:57:26.744042+00:00'
[2024-05-06T21:57:30.576-0500] {taskinstance.py:430} INFO - ::endgroup::
[2024-05-06T21:57:30.582-0500] {logging_mixin.py:188} INFO - An error occurred while exporting data to Excel: The conn_id `mysql_ecommerce` isn't defined
[2024-05-06T21:57:30.583-0500] {taskinstance.py:441} INFO - ::group::Post task execution logs
[2024-05-06T21:57:30.590-0500] {taskinstance.py:2890} ERROR - Task failed with exception
Traceback (most recent call last):
  File "/Users/paulamedina/airflow/dags/first.py", line 13, in export_to_excel
    conn = mysql_hook.get_conn()
           ^^^^^^^^^^^^^^^^^^^^^
  File "/Users/paulamedina/venv/lib/python3.12/site-packages/airflow/providers/mysql/hooks/mysql.py", line 187, in get_conn
    conn = self.connection or self.get_connection(getattr(self, self.conn_name_attr))
                              ^^^^^^^^^^^^^^^^^^^^^^^^^^^^^^^^^^^^^^^^^^^^^^^^^^^^^^^
  File "/Users/paulamedina/venv/lib/python3.12/site-packages/airflow/hooks/base.py", line 83, in get_connection
    conn = Connection.get_connection_from_secrets(conn_id)
           ^^^^^^^^^^^^^^^^^^^^^^^^^^^^^^^^^^^^^^^^^^^^^^^
  File "/Users/paulamedina/venv/lib/python3.12/site-packages/airflow/models/connection.py", line 519, in get_connection_from_secrets
    raise AirflowNotFoundException(f"The conn_id `{conn_id}` isn't defined")
airflow.exceptions.AirflowNotFoundException: The conn_id `mysql_ecommerce` isn't defined

During handling of the above exception, another exception occurred:

Traceback (most recent call last):
  File "/Users/paulamedina/venv/lib/python3.12/site-packages/airflow/models/taskinstance.py", line 465, in _execute_task
    result = _execute_callable(context=context, **execute_callable_kwargs)
             ^^^^^^^^^^^^^^^^^^^^^^^^^^^^^^^^^^^^^^^^^^^^^^^^^^^^^^^^^^^^^
  File "/Users/paulamedina/venv/lib/python3.12/site-packages/airflow/models/taskinstance.py", line 432, in _execute_callable
    return execute_callable(context=context, **execute_callable_kwargs)
           ^^^^^^^^^^^^^^^^^^^^^^^^^^^^^^^^^^^^^^^^^^^^^^^^^^^^^^^^^^^^
  File "/Users/paulamedina/venv/lib/python3.12/site-packages/airflow/models/baseoperator.py", line 400, in wrapper
    return func(self, *args, **kwargs)
           ^^^^^^^^^^^^^^^^^^^^^^^^^^^
  File "/Users/paulamedina/venv/lib/python3.12/site-packages/airflow/operators/python.py", line 235, in execute
    return_value = self.execute_callable()
                   ^^^^^^^^^^^^^^^^^^^^^^^
  File "/Users/paulamedina/venv/lib/python3.12/site-packages/airflow/operators/python.py", line 252, in execute_callable
    return self.python_callable(*self.op_args, **self.op_kwargs)
           ^^^^^^^^^^^^^^^^^^^^^^^^^^^^^^^^^^^^^^^^^^^^^^^^^^^^^
  File "/Users/paulamedina/airflow/dags/first.py", line 25, in export_to_excel
    raise AirflowException(error_message)
airflow.exceptions.AirflowException: An error occurred while exporting data to Excel: The conn_id `mysql_ecommerce` isn't defined
[2024-05-06T21:57:30.599-0500] {taskinstance.py:1205} INFO - Marking task as FAILED. dag_id=mysql_to_excel_report, task_id=export_to_excel, execution_date=20240507T025726, start_date=20240507T025730, end_date=20240507T025730
[2024-05-06T21:57:30.612-0500] {standard_task_runner.py:110} ERROR - Failed to execute job 11 for task export_to_excel (An error occurred while exporting data to Excel: The conn_id `mysql_ecommerce` isn't defined; 65374)
[2024-05-06T21:57:30.663-0500] {local_task_job_runner.py:240} INFO - Task exited with return code 1
[2024-05-06T21:57:30.686-0500] {taskinstance.py:3482} INFO - 0 downstream tasks scheduled from follow-on schedule check
[2024-05-06T21:57:30.690-0500] {local_task_job_runner.py:222} INFO - ::endgroup::
