[2024-05-06T18:42:45.503-0500] {local_task_job_runner.py:120} INFO - ::group::Pre task execution logs
[2024-05-06T18:42:45.522-0500] {taskinstance.py:2073} INFO - Dependencies all met for dep_context=non-requeueable deps ti=<TaskInstance: mysql_to_excel_report.export_to_excel scheduled__2024-05-05T00:00:00+00:00 [queued]>
[2024-05-06T18:42:45.528-0500] {taskinstance.py:2073} INFO - Dependencies all met for dep_context=requeueable deps ti=<TaskInstance: mysql_to_excel_report.export_to_excel scheduled__2024-05-05T00:00:00+00:00 [queued]>
[2024-05-06T18:42:45.528-0500] {taskinstance.py:2303} INFO - Starting attempt 2 of 2
[2024-05-06T18:42:45.539-0500] {taskinstance.py:2327} INFO - Executing <Task(PythonOperator): export_to_excel> on 2024-05-05 00:00:00+00:00
[2024-05-06T18:42:45.549-0500] {logging_mixin.py:188} WARNING - /Users/paulamedina/venv/lib/python3.12/site-packages/airflow/task/task_runner/standard_task_runner.py:61 DeprecationWarning: This process (pid=22292) is multi-threaded, use of fork() may lead to deadlocks in the child.
[2024-05-06T18:42:45.550-0500] {standard_task_runner.py:63} INFO - Started process 22299 to run task
[2024-05-06T18:42:45.549-0500] {standard_task_runner.py:90} INFO - Running: ['airflow', 'tasks', 'run', 'mysql_to_excel_report', 'export_to_excel', 'scheduled__2024-05-05T00:00:00+00:00', '--job-id', '4', '--raw', '--subdir', 'DAGS_FOLDER/first.py', '--cfg-path', '/var/folders/rk/p8h75rkd3ql6mqn01ypzqgnw0000gn/T/tmphol17d6w']
[2024-05-06T18:42:45.551-0500] {standard_task_runner.py:91} INFO - Job 4: Subtask export_to_excel
[2024-05-06T18:42:45.610-0500] {task_command.py:426} INFO - Running <TaskInstance: mysql_to_excel_report.export_to_excel scheduled__2024-05-05T00:00:00+00:00 [running]> on host colpc-c02ylanslvcf.local
[2024-05-06T18:42:45.687-0500] {taskinstance.py:2644} INFO - Exporting env vars: AIRFLOW_CTX_DAG_OWNER='airflow' AIRFLOW_CTX_DAG_ID='mysql_to_excel_report' AIRFLOW_CTX_TASK_ID='export_to_excel' AIRFLOW_CTX_EXECUTION_DATE='2024-05-05T00:00:00+00:00' AIRFLOW_CTX_TRY_NUMBER='2' AIRFLOW_CTX_DAG_RUN_ID='scheduled__2024-05-05T00:00:00+00:00'
[2024-05-06T18:42:45.688-0500] {taskinstance.py:430} INFO - ::endgroup::
[2024-05-06T18:42:45.690-0500] {taskinstance.py:441} INFO - ::group::Post task execution logs
[2024-05-06T18:42:45.695-0500] {taskinstance.py:2890} ERROR - Task failed with exception
Traceback (most recent call last):
  File "/Users/paulamedina/airflow/dags/first.py", line 13, in export_to_excel
    df = pd.read_sql(query, conn_id)
         ^^^^^^^^^^^^^^^^^^^^^^^^^^^
  File "/Users/paulamedina/venv/lib/python3.12/site-packages/pandas/io/sql.py", line 704, in read_sql
    with pandasSQL_builder(con) as pandas_sql:
         ^^^^^^^^^^^^^^^^^^^^^^
  File "/Users/paulamedina/venv/lib/python3.12/site-packages/pandas/io/sql.py", line 903, in pandasSQL_builder
    raise ImportError("Using URI string without sqlalchemy installed.")
ImportError: Using URI string without sqlalchemy installed.

During handling of the above exception, another exception occurred:

Traceback (most recent call last):
  File "/Users/paulamedina/venv/lib/python3.12/site-packages/airflow/models/taskinstance.py", line 465, in _execute_task
    result = _execute_callable(context=context, **execute_callable_kwargs)
             ^^^^^^^^^^^^^^^^^^^^^^^^^^^^^^^^^^^^^^^^^^^^^^^^^^^^^^^^^^^^^
  File "/Users/paulamedina/venv/lib/python3.12/site-packages/airflow/models/taskinstance.py", line 432, in _execute_callable
    return execute_callable(context=context, **execute_callable_kwargs)
           ^^^^^^^^^^^^^^^^^^^^^^^^^^^^^^^^^^^^^^^^^^^^^^^^^^^^^^^^^^^^
  File "/Users/paulamedina/venv/lib/python3.12/site-packages/airflow/models/baseoperator.py", line 400, in wrapper
    return func(self, *args, **kwargs)
           ^^^^^^^^^^^^^^^^^^^^^^^^^^^
  File "/Users/paulamedina/venv/lib/python3.12/site-packages/airflow/operators/python.py", line 235, in execute
    return_value = self.execute_callable()
                   ^^^^^^^^^^^^^^^^^^^^^^^
  File "/Users/paulamedina/venv/lib/python3.12/site-packages/airflow/operators/python.py", line 252, in execute_callable
    return self.python_callable(*self.op_args, **self.op_kwargs)
           ^^^^^^^^^^^^^^^^^^^^^^^^^^^^^^^^^^^^^^^^^^^^^^^^^^^^^
  File "/Users/paulamedina/airflow/dags/first.py", line 21, in export_to_excel
    raise AirflowException(error_message)
airflow.exceptions.AirflowException: An error occurred while exporting data to Excel: Using URI string without sqlalchemy installed.
[2024-05-06T18:42:45.704-0500] {taskinstance.py:1205} INFO - Marking task as FAILED. dag_id=mysql_to_excel_report, task_id=export_to_excel, execution_date=20240505T000000, start_date=20240506T234245, end_date=20240506T234245
[2024-05-06T18:42:45.713-0500] {standard_task_runner.py:110} ERROR - Failed to execute job 4 for task export_to_excel (An error occurred while exporting data to Excel: Using URI string without sqlalchemy installed.; 22299)
[2024-05-06T18:42:45.735-0500] {local_task_job_runner.py:240} INFO - Task exited with return code 1
[2024-05-06T18:42:45.750-0500] {taskinstance.py:3482} INFO - 0 downstream tasks scheduled from follow-on schedule check
[2024-05-06T18:42:45.750-0500] {local_task_job_runner.py:222} INFO - ::endgroup::
